2022-05-21 16:03:21,984 - __main__ - WARNING - WARNING TEST
2022-05-21 16:03:21,984 - __main__ - ERROR - ERROR TEST
2022-05-21 16:03:21,984 - __main__ - CRITICAL - CRITICAL TEST
2022-05-21 16:03:21,985 - __main__ - ERROR - EXCEPTION TEST
NoneType: None
2022-05-21 16:04:00,340 - __main__ - WARNING - WARNING TEST
2022-05-21 16:04:00,340 - __main__ - ERROR - ERROR TEST
2022-05-21 16:04:00,340 - __main__ - CRITICAL - CRITICAL TEST
2022-05-21 16:04:00,340 - __main__ - ERROR - EXCEPTION TEST
NoneType: None
2022-05-21 16:04:11,609 - __main__ - WARNING - WARNING TEST
2022-05-21 16:04:11,609 - __main__ - ERROR - ERROR TEST
2022-05-21 16:04:11,609 - __main__ - CRITICAL - CRITICAL TEST
2022-05-21 16:04:11,609 - __main__ - ERROR - EXCEPTION TEST
NoneType: None
2022-05-21 16:13:23,667 - __main__ - WARNING - WARNING TEST
2022-05-21 16:13:23,668 - __main__ - ERROR - ERROR TEST
2022-05-21 16:13:23,668 - __main__ - CRITICAL - CRITICAL TEST
2022-05-21 16:13:23,669 - __main__ - ERROR - EXCEPTION TEST: division by zero
Traceback (most recent call last):
  File "C:/Users/libuliduobuqiuqiu/Desktop/GitProjects/PythonDemo/Logging/logging_example.py", line 43, in <module>
    a = 1/0
ZeroDivisionError: division by zero
2022-05-21 16:17:46,052 - __main__ - WARNING - WARNING TEST
2022-05-21 16:17:46,053 - __main__ - ERROR - ERROR TEST
2022-05-21 16:17:46,053 - __main__ - CRITICAL - CRITICAL TEST
2022-05-21 16:17:46,054 - __main__ - ERROR - EXCEPTION TEST: division by zero
Traceback (most recent call last):
  File "C:/Users/libuliduobuqiuqiu/Desktop/GitProjects/PythonDemo/Logging/logging_example.py", line 44, in <module>
    a = 1/0
ZeroDivisionError: division by zero
2022-05-21 16:17:59,718 - __main__ - WARNING - WARNING TEST
2022-05-21 16:17:59,719 - __main__ - ERROR - ERROR TEST
2022-05-21 16:17:59,719 - __main__ - CRITICAL - CRITICAL TEST
2022-05-21 16:17:59,719 - __main__ - ERROR - EXCEPTION TEST: division by zero
Traceback (most recent call last):
  File "C:/Users/libuliduobuqiuqiu/Desktop/GitProjects/PythonDemo/Logging/logging_example.py", line 44, in <module>
    a = 1/0
ZeroDivisionError: division by zero
2022-05-21 16:18:48,501 - __main__ - WARNING - WARNING TEST
2022-05-21 16:18:48,502 - __main__ - ERROR - ERROR TEST
2022-05-21 16:18:48,502 - __main__ - CRITICAL - CRITICAL TEST
2022-05-21 16:18:48,502 - __main__ - ERROR - EXCEPTION TEST: division by zero
Traceback (most recent call last):
  File "C:/Users/libuliduobuqiuqiu/Desktop/GitProjects/PythonDemo/Logging/logging_example.py", line 44, in <module>
    a = 1/0
ZeroDivisionError: division by zero
2022-05-22 09:15:01 - __main__ - WARNING - WARNING TEST
2022-05-22 09:15:01 - __main__ - ERROR - ERROR TEST
2022-05-22 09:15:01 - __main__ - CRITICAL - CRITICAL TEST
2022-05-22 09:15:01 - __main__ - ERROR - EXCEPTION TEST: division by zero
Traceback (most recent call last):
  File "C:/Users/libuliduobuqiuqiu/Desktop/GitProjects/PythonDemo/Logging/logging_example.py", line 45, in <module>
    a = 1/0
ZeroDivisionError: division by zero
WARNING TEST
ERROR TEST
CRITICAL TEST
EXCEPTION TEST: division by zero
Traceback (most recent call last):
  File "C:/Users/libuliduobuqiuqiu/Desktop/GitProjects/PythonDemo/Logging/logging_example.py", line 46, in <module>
    a = 1/0
ZeroDivisionError: division by zero
2022-05-22 09:30:46 - __main__ - WARNING - WARNING TEST
2022-05-22 09:30:46 - __main__ - ERROR - ERROR TEST
2022-05-22 09:30:46 - __main__ - CRITICAL - CRITICAL TEST
2022-05-22 09:30:46 - __main__ - ERROR - EXCEPTION TEST: division by zero
Traceback (most recent call last):
  File "C:/Users/libuliduobuqiuqiu/Desktop/GitProjects/PythonDemo/Logging/logging_example.py", line 45, in <module>
    a = 1/0
ZeroDivisionError: division by zero
2022-05-22 09:35:49 - __main__ - WARNING - WARNING TEST
2022-05-22 09:35:49 - __main__ - ERROR - ERROR TEST
2022-05-22 09:35:49 - __main__ - CRITICAL - CRITICAL TEST
2022-05-22 09:35:49 - __main__ - ERROR - EXCEPTION TEST: division by zero
Traceback (most recent call last):
  File "C:/Users/libuliduobuqiuqiu/Desktop/GitProjects/PythonDemo/Logging/logging_example.py", line 45, in <module>
    a = 1/0
ZeroDivisionError: division by zero
2022-05-28 16:05:41 - __main__ - WARNING - WARNING TEST
2022-05-28 16:05:41 - __main__ - ERROR - ERROR TEST
2022-05-28 16:05:41 - __main__ - CRITICAL - CRITICAL TEST
2022-05-28 16:05:41 - __main__ - ERROR - EXCEPTION TEST: division by zero
Traceback (most recent call last):
  File "C:/Users/libuliduobuqiuqiu/Desktop/GitProjects/PythonDemo/Logging/logging_example.py", line 45, in <module>
    a = 1/0
ZeroDivisionError: division by zero
2022-05-28 16:05:45 - __main__ - WARNING - WARNING TEST
2022-05-28 16:05:45 - __main__ - ERROR - ERROR TEST
2022-05-28 16:05:45 - __main__ - CRITICAL - CRITICAL TEST
2022-05-28 16:05:45 - __main__ - ERROR - EXCEPTION TEST: division by zero
Traceback (most recent call last):
  File "C:/Users/libuliduobuqiuqiu/Desktop/GitProjects/PythonDemo/Logging/logging_example.py", line 45, in <module>
    a = 1/0
ZeroDivisionError: division by zero
2022-05-28 16:06:13 - __main__ - WARNING - WARNING TEST
2022-05-28 16:06:13 - __main__ - ERROR - ERROR TEST
2022-05-28 16:06:13 - __main__ - CRITICAL - CRITICAL TEST
2022-05-28 16:06:13 - __main__ - ERROR - EXCEPTION TEST: division by zero
Traceback (most recent call last):
  File "logging_example.py", line 45, in <module>
    a = 1/0
ZeroDivisionError: division by zero
2022-05-28 16:06:25 - __main__ - WARNING - WARNING TEST
2022-05-28 16:06:25 - __main__ - ERROR - ERROR TEST
2022-05-28 16:06:25 - __main__ - CRITICAL - CRITICAL TEST
2022-05-28 16:06:25 - __main__ - ERROR - EXCEPTION TEST: division by zero
Traceback (most recent call last):
  File "C:\Users\libuliduobuqiuqiu\Desktop\GitProjects\PythonDemo\Logging\logging_example.py", line 45, in <module>
    a = 1/0
ZeroDivisionError: division by zero
